Workbook

Sheet Exhibit 1 

Sheet Exhibit 2

Sheet Financials 
A2: Income Statement - Twitter
B4: 2019 | C4: 2020 | D4: 2021
A5: Revenue | B5: 3459.33 | C5: 3716.35 | D5: 5077.48
A6: Growth | C6: =C5/B5-1 -> 0.074297624 | D6: =D5/C5-1 -> 0.36625452
A7: Recurring Operating Expenses | B7: -3092.96 | C7: -3689.69 | D7: -4804.52
A8: Non-Recurring Operating Expenses | D8: -765.7
A9: Operating Income (Loss) | B9: 366.37 | C9: 26.66 | D9: -492.74
A10: Operating Margin (%) | B10: =10.59/100 -> 0.1059 | C10: 0.0072 | D10: =D9/D5 -> -0.097044203
A11: Depreciation & Amortization | B11: 465.5 | C11: 495.18 | D11: 544.85
A12: EBITDA | B12: 831.87 | C12: 521.84 | D12: 817.81
A13: EBITDA Margin (%) | B13: =24.05/100 -> 0.2405 | C13: =14.04/100 -> 0.1404 | D13: =16.11/100 -> 0.1611
A14: Interest Expense | B14: -138.18 | C14: -152.88 | D14: -51.19
A15: Interest Income | B15: 157.7 | C15: 88.18 | D15: 35.68
A16: Other Income (Expense) | B16: 4.24 | C16: -12.9 | D16: 97.13
A17: Net Interest Income (Expense) | B17: 23.77 | C17: -77.6 | D17: 81.63
A18: Taxable Income | B18: 390.14 | C18: -50.94 | D18: -411.11
A19: Income Tax Provision | B19: 1075.52 | C19: -1084.69 | D19: 189.7
A20: Net Income (Loss) | B20: 1465.66 | C20: -1135.63 | D20: -221.41
A22: Balance Sheet
B24: 2019 | C24: 2020 | D24: 2021
A25: Cash & Equivalents | B25: 1799.08 | C25: 1988.43 | D25: 2186.55
A26: Short-term Investments | B26: 4839.97 | C26: 5483.87 | D26: 4207.13
A27: Total Current Assets | B27: 7620.08 | C27: 8637.11 | D27: 7918.37
A28: Property & Equipment (Net) | B28: 1031.78 | C28: 1493.79 | D28: 2082.16
A29: Intangible Assets (Net) | B29: 55.11 | C29: 58.34 | D29: 69.32
A30: Goodwill | B30: 1256.7 | C30: 1312.35 | D30: 1301.52
A31: Total Assets | B31: 12703.39 | C31: 13379.09 | D31: 14059.52
A32: Convertible Notes (Short-term) | C32: 917.87
A33: Total Current Liabilities | B33: 832.48 | C33: 1952.83 | D33: 1343.87
A34: Convertible Notes (Long-term) | B34: 1816.83 | C34: 1875.88 | D34: 3559.02
A35: Senior Notes (Long-term) | B35: 691.97 | C35: 692.99 | D35: 694
A36: Total Liabilities | B36: 3999 | C36: 5409.01 | D36: 6752.32
A37: Total Stockholders Equity | B37: 8704.39 | C37: 7970.08 | D37: 7307.2
A38: Total Liab & Equity | B38: =B36+B37 -> 12703.39 | C38: =C36+C37 -> 13379.09 | D38: =D36+D37 -> 14059.52

Sheet Transaction Summary
A2: Sources and Uses for Twitter
A3: (in millions of U.S. dollars)
A5: Sources | E5: Uses
A6: New Debt | C6: 25000 | E6: Purchase Of Public Equity | F6: 39431
A7: Existing Cash | C7: 6394 | E7: Buyout | F7: 3962
A8: Equity | C8: 21000 | E8: Fees and expenses | F8: 500
A9: Equity Rollover | B9: 3962 | E9: Refinancing of existing debt | F9: 4476
A10: Sponsor's Equity | B10: 17038 | E10: Minimum Cash | F10: 4025
A11: Total Sources | C11: =SUM(C6:C8) -> 52394 | E11: Total Uses | F11: =SUM(F6:F10) -> 52394
B13: Transaction Summary (All Amounts in Million, Except per Share Data)
A15: Public Shares | B15: 727.5 | C15: =B15/B17 -> 0.90869348
A16: Elon Musk's Shares | B16: 73.1 | C16: =B16/B17 -> 0.09130652
A17: Total Shares | B17: =SUM(B15:B16) -> 800.6
A19: Musk's Bid Price | B19: 54.2
A20: Implied Equity Value | B20: 43393
A22: Debt | B22: 4253
A23: Cash | B23: -6394
A24: Implied Transaction Value | B24: =B20+B22+B23 -> 41252

Sheet Projected Financials (Best Case
A1: Assumptions:
A3: Metric | B3: 2021A | C3: 2022E | D3: 2023E | E3: 2024E | F3: 2025E | G3: 2026E | H3: 2027E | I3: 2028E
A4: Revenue Growth | B4: 0.3663 | C4: 0.25 | D4: 0.15 | E4: 0.15 | F4: 0.15 | G4: 0.15 | H4: 0.15 | I4: 0.1
A5: Depreciation & Amortization | D5: 0.095 | E5: 0.09 | F5: 0.085 | G5: 0.08 | H5: 0.075
A6: EBITDA Margin | B6: 0.1611 | D6: 0.25 | E6: 0.25 | F6: 0.25 | G6: 0.25 | H6: 0.25
A7: CapEx (% Revenue) | D7: 0.1 | E7: 0.1 | F7: 0.1 | G7: 0.1 | H7: 0.1
A8: Change in NWC (% Rev Change) | D8: 0.01 | E8: 0.01 | F8: 0.01 | G8: 0.01 | H8: 0.01
A9: Terminal EBITDA Multiple | H9: 25
A10: Debt | C10: 25000
A11: Interest Rate | C11: 0.07
A12: Tax Rate | C12: 0.28
A13: Required Return (Musk) | C13: 0.25
A14: Required Return (Sponsors) | C14: 0.25
B17: 2021 | C17: 2022E | D17: 2023E | E17: 2024E | F17: 2025E | G17: 2026E | H17: 2027E
A18: Revenue | B18: ='Financials '!D5 -> 5077.48 | C18: =B18*(1+C4) -> 6346.85 | D18: =C18*(1+D4) -> 7298.8775 | E18: =D18*(1+E4) -> 8393.7091 | F18: =E18*(1+F4) -> 9652.7655 | G18: =F18*(1+G4) -> 11100.68 | H18: =G18*(1+H4) -> 12765.782
A19: Revenue Growth | B19: ='Financials '!D6 -> 0.36625452 | C19: =C18/B18-1 -> 0.25 | D19: =D18/C18-1 -> 0.15 | E19: =E18/D18-1 -> 0.15 | F19: =F18/E18-1 -> 0.15 | G19: =G18/F18-1 -> 0.15 | H19: =H18/G18-1 -> 0.15
A20: EBITDA | B20: ='Financials '!D12 -> 817.81 | C20: =C18*C21 -> 1343.6281 | D20: =D18*0.25 -> 1824.7194 | E20: =E18*0.25 -> 2098.4273 | F20: =F18*0.25 -> 2413.1914 | G20: =G18*0.25 -> 2775.1701 | H20: =H18*0.25 -> 3191.4456
A21: EBITDA Margin | B21: =B20/B18 -> 0.16106612 | C21: 0.2117 | D21: =D20/D18 -> 0.25 | E21: =E20/E18 -> 0.25 | F21: =F20/F18 -> 0.25 | G21: =G20/G18 -> 0.25 | H21: =H20/H18 -> 0.25
A22: Depreciation & Amortization | B22: ='Financials '!D11 -> 544.85 | C22: =C20-C23 -> 431.5858 | D22: =D5*D18 -> 693.39336 | E22: =E5*E18 -> 755.43382 | F22: =F5*F18 -> 820.48507 | G22: =G5*G18 -> 888.05443 | H22: =H5*H18 -> 957.43368
A23: EBIT | B23: =B20-B22 -> 272.96 | C23: =C18*14.37% -> 912.04234 | D23: =D20-D22 -> 1131.326 | E23: =E20-E22 -> 1342.9935 | F23: =F20-F22 -> 1592.7063 | G23: =G20-G22 -> 1887.1157 | H23: =H20-H22 -> 2234.0119
A24: EBIT Margin | B24: =B23/B18 -> 0.053758951 | C24: =C23/C18 -> 0.1437 | D24: =D23/D18 -> 0.155 | E24: =E23/E18 -> 0.16 | F24: =F23/F18 -> 0.165 | G24: =G23/G18 -> 0.17 | H24: =H23/H18 -> 0.175
A25: Interest Expense | B25: ='Financials '!D17 -> 81.63 | C25: =C11*C10 -> 1750 | D25: =C25 -> 1750 | E25: =D25 -> 1750 | F25: =E25 -> 1750 | G25: =F25 -> 1750 | H25: =G25 -> 1750
A26: EBT | B26: ='Financials '!D18 -> -411.11 | C26: =C23-C25 -> -837.95766 | D26: =D23-D25 -> -618.67399 | E26: =E23-E25 -> -407.00654 | F26: =F23-F25 -> -157.29369 | G26: =G23-G25 -> 137.11565 | H26: =H23-H25 -> 484.01191
A27: Taxes | B27: ='Financials '!D19 -> 189.7 | C27: 0 | D27: 0 | E27: 0 | F27: 0 | G27: =$C$12*G26 -> 38.392383 | H27: =$C$12*H26 -> 135.52334
A28: Net Income | B28: =B26+B27 -> -221.41 | C28: =C26+C27 -> -837.95766 | D28: =D26+D27 -> -618.67399 | E28: =E26+E27 -> -407.00654 | F28: =F26+F27 -> -157.29369 | G28: =G26-G27 -> 98.723271 | H28: =H26-H27 -> 348.48858
A29: Net Margin | B29: =B28/B18 -> -0.043606277 | C29: =C28/C18 -> -0.13202733 | D29: =D28/D18 -> -0.084762895 | E29: =E28/E18 -> -0.048489474 | F29: =F28/F18 -> -0.016295195 | G29: =G28/G18 -> 0.0088934433 | H29: =H28/H18 -> 0.027298646
A30: CapEx | C30: =C18*10% -> 634.685 | D30: =D18*10% -> 729.88775 | E30: =E18*10% -> 839.37091 | F30: =F18*10% -> 965.27655 | G30: =G18*10% -> 1110.068 | H30: =H18*10% -> 1276.5782
A31: =A22 -> Depreciation & Amortization | C31: =C22 -> 431.5858 | D31: =D22 -> 693.39336 | E31: =E22 -> 755.43382 | F31: =F22 -> 820.48507 | G31: =G22 -> 888.05443 | H31: =H22 -> 957.43368
A32: Change in NWC | C32: =0.01*(C18-B18) -> 12.6937 | D32: =0.01*(D18-C18) -> 9.520275 | E32: =0.01*(E18-D18) -> 10.948316 | F32: =0.01*(F18-E18) -> 12.590564 | G32: =0.01*(G18-F18) -> 14.479148 | H32: =0.01*(H18-G18) -> 16.65102
A33: Cash Flow Available to Repay Debt | C33: =C28-C30+C31-C32 -> -1053.7506 | D33: =D28-D30+D31-D32 -> -664.68865 | E33: =E28-E30+E31-E32 -> -501.89195 | F33: =F28-F30+F31-F32 -> -314.67574 | G33: =G28-G30+G31-G32 -> -137.76948 | H33: =H28-H30+H31-H32 -> 12.692998
A34: Debt Draw / Repayment | C34: - | D34: - | E34: - | F34: - | G34: - | H34: -
A35: Cash Flow to Equity | C35: =C33 -> -1053.7506 | D35: =D33 -> -664.68865 | E35: =E33 -> -501.89195 | F35: =F33 -> -314.67574 | G35: =G33 -> -137.76948 | H35: =H33 -> 12.692998
A36: Terminal Value | H36: ='Return Analysis'!G6 -> 79786.14
A37: Terminal Equity Value | H37: ='Return Analysis'!G9 -> 55637.359
A38: CF to Equity + TVE | H38: =H37+H35 -> 55650.052
A39: PV of Equity | H39: =H38/(1.25)^6 -> 14588.327
A40: Excess Cash | H40: ='Financials '!D25-'Transaction Summary'!F10 -> -1838.45
A41: Equity Value | H41: =H38+H40 -> 53811.602
A42: Implied Share Price | H42: =H41/'Transaction Summary'!B17 -> 67.214092 | K42: =-'Transaction Summary'!B9 -> -3962 | L42: 0 | M42: 0 | N42: 0 | O42: 0 | P42: =B47 -> 10152.456
A44: Elon Musk's Split | B44: ='Transaction Summary'!B9/'Transaction Summary'!C8 -> 0.18866667
...

Sheet  Projected Financials (Base Cas
A1: Assumptions:
A3: Metric | B3: 2021A | C3: 2022E | D3: 2023E | E3: 2024E | F3: 2025E | G3: 2026E | H3: 2027E | I3: 2028E
A4: Revenue Growth | B4: 0.3663 | C4: 0.25 | D4: 0.125 | E4: 0.125 | F4: 0.125 | G4: 0.125 | H4: 0.125 | I4: 0.1
A5: Depreciation & Amortization | D5: 0.095 | E5: 0.09 | F5: 0.085 | G5: 0.08 | H5: 0.075
A6: EBITDA Margin | B6: 0.1611 | D6: 0.225 | E6: 0.225 | F6: 0.225 | G6: 0.225 | H6: 0.225
A7: CapEx (% Revenue) | D7: 0.1 | E7: 0.1 | F7: 0.1 | G7: 0.1 | H7: 0.1
A8: Change in NWC (% Rev Change) | D8: 0.01 | E8: 0.01 | F8: 0.01 | G8: 0.01 | H8: 0.01
A9: Terminal EBITDA Multiple | H9: 22.5
A10: Debt | C10: 25000
A11: Interest Rate | C11: 0.07
A12: Tax Rate | C12: 0.28
A13: Required Return (Musk) | C13: 0.25
A14: Required Return (Sponsors) | C14: 0.25
B17: 2021 | C17: 2022E | D17: 2023E | E17: 2024E | F17: 2025E | G17: 2026E | H17: 2027E
A18: Revenue | B18: ='Financials '!D5 -> 5077.48 | C18: =B18*(1+C4) -> 6346.85 | D18: =C18*(1+D4) -> 7140.2063 | E18: =D18*(1+E4) -> 8032.732 | F18: =E18*(1+F4) -> 9036.8235 | G18: =F18*(1+G4) -> 10166.426 | H18: =G18*(1+H4) -> 11437.23
A19: Revenue Growth | B19: ='Financials '!D6 -> 0.36625452 | C19: =C18/B18-1 -> 0.25 | D19: =D18/C18-1 -> 0.125 | E19: =E18/D18-1 -> 0.125 | F19: =F18/E18-1 -> 0.125 | G19: =G18/F18-1 -> 0.125 | H19: =H18/G18-1 -> 0.125
A20: EBITDA | B20: ='Financials '!D12 -> 817.81 | C20: =C18*C21 -> 1343.6281 | D20: =D18*0.225 -> 1606.5464 | E20: =E18*0.225 -> 1807.3647 | F20: =F18*0.225 -> 2033.2853 | G20: =G18*0.225 -> 2287.446 | H20: =H18*0.225 -> 2573.3767
A21: EBITDA Margin | B21: =B20/B18 -> 0.16106612 | C21: 0.2117 | D21: =D20/D18 -> 0.225 | E21: =E20/E18 -> 0.225 | F21: =F20/F18 -> 0.225 | G21: =G20/G18 -> 0.225 | H21: =H20/H18 -> 0.225
A22: Depreciation & Amortization | B22: ='Financials '!D11 -> 544.85 | C22: =C20-C23 -> 431.5858 | D22: =D5*D18 -> 678.31959 | E22: =E5*E18 -> 722.94588 | F22: =F5*F18 -> 768.13 | G22: =G5*G18 -> 813.31412 | H22: =H5*H18 -> 857.79223
A23: EBIT | B23: =B20-B22 -> 272.96 | C23: =C18*14.37% -> 912.04234 | D23: =D20-D22 -> 928.22681 | E23: =E20-E22 -> 1084.4188 | F23: =F20-F22 -> 1265.1553 | G23: =G20-G22 -> 1474.1318 | H23: =H20-H22 -> 1715.5845
A24: EBIT Margin | B24: =B23/B18 -> 0.053758951 | C24: =C23/C18 -> 0.1437 | D24: =D23/D18 -> 0.13 | E24: =E23/E18 -> 0.135 | F24: =F23/F18 -> 0.14 | G24: =G23/G18 -> 0.145 | H24: =H23/H18 -> 0.15
A25: Interest Expense | B25: ='Financials '!D17 -> 81.63 | C25: =C11*C10 -> 1750 | D25: =C25 -> 1750 | E25: =D25 -> 1750 | F25: =E25 -> 1750 | G25: =F25 -> 1750 | H25: =G25 -> 1750
A26: EBT | B26: ='Financials '!D18 -> -411.11 | C26: =C23-C25 -> -837.95766 | D26: =D23-D25 -> -821.77319 | E26: =E23-E25 -> -665.58118 | F26: =F23-F25 -> -484.84471 | G26: =G23-G25 -> -275.86816 | H26: =H23-H25 -> -34.415532
A27: Taxes | B27: ='Financials '!D19 -> 189.7 | C27: 0 | D27: 0 | E27: 0 | F27: 0 | G27: 0 | H27: 0
A28: Net Income | B28: =B26+B27 -> -221.41 | C28: =C26+C27 -> -837.95766 | D28: =D26+D27 -> -821.77319 | E28: =E26+E27 -> -665.58118 | F28: =F26+F27 -> -484.84471 | G28: =G26+G27 -> -275.86816 | H28: =H26+H27 -> -34.415532
A29: Net Margin | B29: =B28/B18 -> -0.043606277 | C29: =C28/C18 -> -0.13202733 | D29: =D28/D18 -> -0.11509096 | E29: =E28/E18 -> -0.082858631 | F29: =F28/F18 -> -0.053652116 | G29: =G28/G18 -> -0.027135214 | H29: =H28/H18 -> -0.0030090794
A30: CapEx | C30: =C18*10% -> 634.685 | D30: =D18*10% -> 714.02062 | E30: =E18*10% -> 803.2732 | F30: =F18*10% -> 903.68235 | G30: =G18*10% -> 1016.6426 | H30: =H18*10% -> 1143.723
A31: =A22 -> Depreciation & Amortization | C31: =C22 -> 431.5858 | D31: =D22 -> 678.31959 | E31: =E22 -> 722.94588 | F31: =F22 -> 768.13 | G31: =G22 -> 813.31412 | H31: =H22 -> 857.79223
A32: Change in NWC | C32: =0.01*(C18-B18) -> 12.6937 | D32: =0.01*(D18-C18) -> 7.9335625 | E32: =0.01*(E18-D18) -> 8.9252578 | F32: =0.01*(F18-E18) -> 10.040915 | G32: =0.01*(G18-F18) -> 11.296029 | H32: =0.01*(H18-G18) -> 12.708033
A33: Cash Flow Available to Repay Debt | C33: =C28-C30+C31-C32 -> -1053.7506 | D33: =D28-D30+D31-D32 -> -865.40778 | E33: =E28-E30+E31-E32 -> -754.83375 | F33: =F28-F30+F31-F32 -> -630.43797 | G33: =G28-G30+G31-G32 -> -490.49272 | H33: =H28-H30+H31-H32 -> -333.05431
A34: Debt Draw / Repayment | C34: - | D34: - | E34: - | F34: - | G34: - | H34: -
A35: Cash Flow to Equity | C35: =C33 -> -1053.7506 | D35: =D33 -> -865.40778 | E35: =E33 -> -754.83375 | F35: =F33 -> -630.43797 | G35: =G33 -> -490.49272 | H35: =H33 -> -333.05431
A36: Terminal Value | H36: =H20*22.5 -> 57900.976
A37: Terminal Equity Value | H37: =H36-24148.78 -> 33752.196
A38: CF to Equity + TVE | H38: =H37+H35 -> 33419.141
A39: PV of Equity | H39: =H38/(1.25)^6 -> 8760.6274
A40: Excess Cash | H40: ='Financials '!D25-'Transaction Summary'!F10 -> -1838.45
A41: Equity Value | H41: =H38+H40 -> 31580.691
A42: Implied Share Price | H42: =H41/'Transaction Summary'!B17 -> 39.44628 | K42: =-'Transaction Summary'!B9 -> -3962 | L42: 0 | M42: 0 | N42: 0 | O42: 0 | P42: =B47 -> 5958.2238
A44: Elon Musk's Split | B44: ='Transaction Summary'!B9/'Transaction Summary'!C8 -> 0.18866667
...

Sheet  Projected Financials (Worst ca
A1: Assumptions:
A3: Metric | B3: 2021A | C3: 2022E | D3: 2023E | E3: 2024E | F3: 2025E | G3: 2026E | H3: 2027E | I3: 2028E
A4: Revenue Growth | B4: 0.3663 | C4: 0.25 | D4: 0.1 | E4: 0.1 | F4: 0.1 | G4: 0.1 | H4: 0.1 | I4: 0.08
A5: Depreciation & Amortization | D5: 0.095 | E5: 0.09 | F5: 0.085 | G5: 0.08 | H5: 0.075
A6: EBITDA Margin | B6: 0.1611 | D6: 0.2 | E6: 0.2 | F6: 0.2 | G6: 0.2 | H6: 0.2
A7: CapEx (% Revenue) | D7: 0.1 | E7: 0.1 | F7: 0.1 | G7: 0.1 | H7: 0.1
A8: Change in NWC (% Rev Change) | D8: 0.01 | E8: 0.01 | F8: 0.01 | G8: 0.01 | H8: 0.01
A9: Terminal EBITDA Multiple | H9: 20
A10: Debt | C10: 25000
A11: Interest Rate | C11: 0.07
A12: Tax Rate | C12: 0.28
A13: Required Return (Musk) | C13: 0.25
A14: Required Return (Sponsors) | C14: 0.25
B17: 2021 | C17: 2022E | D17: 2023E | E17: 2024E | F17: 2025E | G17: 2026E | H17: 2027E
A18: Revenue | B18: ='Financials '!D5 -> 5077.48 | C18: =B18*(1+C4) -> 6346.85 | D18: =C18*(1+D4) -> 6981.535 | E18: =D18*(1+E4) -> 7679.6885 | F18: =E18*(1+F4) -> 8447.6573 | G18: =F18*(1+G4) -> 9292.4231 | H18: =G18*(1+H4) -> 10221.665
A19: Revenue Growth | B19: ='Financials '!D6 -> 0.36625452 | C19: =C18/B18-1 -> 0.25 | D19: =D18/C18-1 -> 0.1 | E19: =E18/D18-1 -> 0.1 | F19: =F18/E18-1 -> 0.1 | G19: =G18/F18-1 -> 0.1 | H19: =H18/G18-1 -> 0.1
A20: EBITDA | B20: ='Financials '!D12 -> 817.81 | C20: =C18*C21 -> 1343.6281 | D20: =D18*0.2 -> 1396.307 | E20: =E18*0.2 -> 1535.9377 | F20: =F18*0.2 -> 1689.5315 | G20: =G18*0.2 -> 1858.4846 | H20: =H18*0.2 -> 2044.3331
A21: EBITDA Margin | B21: =B20/B18 -> 0.16106612 | C21: 0.2117 | D21: =D20/D18 -> 0.2 | E21: =E20/E18 -> 0.2 | F21: =F20/F18 -> 0.2 | G21: =G20/G18 -> 0.2 | H21: =H20/H18 -> 0.2
A22: Depreciation & Amortization | B22: ='Financials '!D11 -> 544.85 | C22: =C20-C23 -> 431.5858 | D22: =D5*D18 -> 663.24582 | E22: =E5*E18 -> 691.17197 | F22: =F5*F18 -> 718.05087 | G22: =G5*G18 -> 743.39385 | H22: =H5*H18 -> 766.6249
A23: EBIT | B23: =B20-B22 -> 272.96 | C23: =C18*14.37% -> 912.04234 | D23: =D20-D22 -> 733.06118 | E23: =E20-E22 -> 844.76573 | F23: =F20-F22 -> 971.4806 | G23: =G20-G22 -> 1115.0908 | H23: =H20-H22 -> 1277.7082
A24: EBIT Margin | B24: =B23/B18 -> 0.053758951 | C24: =C23/C18 -> 0.1437 | D24: =D23/D18 -> 0.105 | E24: =E23/E18 -> 0.11 | F24: =F23/F18 -> 0.115 | G24: =G23/G18 -> 0.12 | H24: =H23/H18 -> 0.125
A25: Interest Expense | B25: ='Financials '!D17 -> 81.63 | C25: =C11*C10 -> 1750 | D25: =C25 -> 1750 | E25: =D25 -> 1750 | F25: =E25 -> 1750 | G25: =F25 -> 1750 | H25: =G25 -> 1750
A26: EBT | B26: ='Financials '!D18 -> -411.11 | C26: =C23-C25 -> -837.95766 | D26: =D23-D25 -> -1016.9388 | E26: =E23-E25 -> -905.23427 | F26: =F23-F25 -> -778.5194 | G26: =G23-G25 -> -634.90923 | H26: =H23-H25 -> -472.29183
A27: Taxes | B27: ='Financials '!D19 -> 189.7 | C27: 0 | D27: 0 | E27: 0 | F27: 0 | G27: 0 | H27: 0
A28: Net Income | B28: =B26+B27 -> -221.41 | C28: =C26+C27 -> -837.95766 | D28: =D26+D27 -> -1016.9388 | E28: =E26+E27 -> -905.23427 | F28: =F26+F27 -> -778.5194 | G28: =G26+G27 -> -634.90923 | H28: =H26+H27 -> -472.29183
A29: Net Margin | B29: =B28/B18 -> -0.043606277 | C29: =C28/C18 -> -0.13202733 | D29: =D28/D18 -> -0.14566121 | E29: =E28/E18 -> -0.11787383 | F29: =F28/F18 -> -0.092158024 | G29: =G28/G18 -> -0.068325476 | H29: =H28/H18 -> -0.046204978
A30: CapEx | C30: =C18*10% -> 634.685 | D30: =D18*10% -> 698.1535 | E30: =E18*10% -> 767.96885 | F30: =F18*10% -> 844.76573 | G30: =G18*10% -> 929.24231 | H30: =H18*10% -> 1022.1665
A31: =A22 -> Depreciation & Amortization | C31: =C22 -> 431.5858 | D31: =D22 -> 663.24582 | E31: =E22 -> 691.17197 | F31: =F22 -> 718.05087 | G31: =G22 -> 743.39385 | H31: =H22 -> 766.6249
A32: Change in NWC | C32: =0.01*(C18-B18) -> 12.6937 | D32: =0.01*(D18-C18) -> 6.34685 | E32: =0.01*(E18-D18) -> 6.981535 | F32: =0.01*(F18-E18) -> 7.6796885 | G32: =0.01*(G18-F18) -> 8.4476574 | H32: =0.01*(H18-G18) -> 9.2924231
A33: Cash Flow Available to Repay Debt | C33: =C28-C30+C31-C32 -> -1053.7506 | D33: =D28-D30+D31-D32 -> -1058.1934 | E33: =E28-E30+E31-E32 -> -989.01269 | F33: =F28-F30+F31-F32 -> -912.91395 | G33: =G28-G30+G31-G32 -> -829.20535 | H33: =H28-H30+H31-H32 -> -737.12588
A34: Debt Draw / Repayment | C34: - | D34: - | E34: - | F34: - | G34: - | H34: -
A35: Cash Flow to Equity | C35: =C33 -> -1053.7506 | D35: =D33 -> -1058.1934 | E35: =E33 -> -989.01269 | F35: =F33 -> -912.91395 | G35: =G33 -> -829.20535 | H35: =H33 -> -737.12588
A36: Terminal Value | H36: =H20*20 -> 40886.662
A37: Terminal Equity Value | H37: =H36-24148.78 -> 16737.882
A38: CF to Equity + TVE | H38: =H37+H35 -> 16000.756
A39: PV of Equity | H39: =H38/(1.25)^6 -> 4194.5021
A40: Excess Cash | H40: ='Financials '!D25-'Transaction Summary'!F10 -> -1838.45
A41: Equity Value | H41: =H38+H40 -> 14162.306
A42: Implied Share Price | H42: =H41/'Transaction Summary'!B17 -> 17.689615 | K42: =-'Transaction Summary'!B9 -> -3962 | L42: 0 | M42: 0 | N42: 0 | O42: 0 | P42: =B47 -> 2671.955
A44: Elon Musk's Split | B44: ='Transaction Summary'!B9/'Transaction Summary'!C8 -> 0.18866667
...

Sheet Debt Schedule 
A1: Debt Schedule for Twitter
A2: (millions of USD)
C3: 2022 | D3: 2023 | E3: 2024 | F3: 2025 | G3: 2026 | H3: 2027
A4: Senior Loan | B4: 0.08 | C4: 9500 | D4: =C6 -> 9500 | E4: =D6 -> 9500 | F4: =E6 -> 9500 | G4: =F6 -> 9500 | H4: =G6 -> 9500 | J4: =H6+H11+H16 -> 24961.921
A5: Repayment | C5: =MAX(0,MIN('Projected Financials (Best Case'!C35,C4)) -> 0 | D5: =MAX(0,MIN('Projected Financials (Best Case'!D35,D4)) -> 0 | E5: =MAX(0,MIN('Projected Financials (Best Case'!E35,E4)) -> 0 | F5: =MAX(0,MIN('Projected Financials (Best Case'!F35,F4)) -> 0 | G5: =MAX(0,MIN('Projected Financials (Best Case'!G35,G4)) -> 0 | H5: =MAX(0,MIN('Projected Financials (Best Case'!H35,H4)) -> 12.692998
A6: Ending Balance | C6: =C4-C5 -> 9500 | D6: =D4-D5 -> 9500 | E6: =E4-E5 -> 9500 | F6: =F4-F5 -> 9500 | G6: =G4-G5 -> 9500 | H6: =H4-H5 -> 9487.307
A7: Interest | C7: =C4*$B$4 -> 760 | D7: =D4*$B$4 -> 760 | E7: =E4*$B$4 -> 760 | F7: =F4*$B$4 -> 760 | G7: =G4*$B$4 -> 760 | H7: =H4*$B$4 -> 760
A9: Unsecured Loan | B9: 0.1 | C9: =3000 -> 3000 | D9: =C11 -> 3000 | E9: =D11 -> 3000 | F9: =E11 -> 3000 | G9: =F11 -> 3000 | H9: =G11 -> 3000
A10: Repayment | C10: =MAX(0,MIN('Projected Financials (Best Case'!C35,C9)) -> 0 | D10: =MAX(0,MIN('Projected Financials (Best Case'!D35,D9)) -> 0 | E10: =MAX(0,MIN('Projected Financials (Best Case'!E35,E9)) -> 0 | F10: =MAX(0,MIN('Projected Financials (Best Case'!F35,F9)) -> 0 | G10: =MAX(0,MIN('Projected Financials (Best Case'!G35,G9)) -> 0 | H10: =MAX(0,MIN('Projected Financials (Best Case'!H35,H9)) -> 12.692998
A11: Ending Balance | C11: =C9-C10 -> 3000 | D11: =D9-D10 -> 3000 | E11: =E9-E10 -> 3000 | F11: =F9-F10 -> 3000 | G11: =G9-G10 -> 3000 | H11: =H9-H10 -> 2987.307
A12: Interest | C12: =C9*$B$9 -> 300 | D12: =D9*$B$9 -> 300 | E12: =E9*$B$9 -> 300 | F12: =F9*$B$9 -> 300 | G12: =G9*$B$9 -> 300 | H12: =H9*$B$9 -> 300
A14: Margin Loan | B14: SOFR + 3% | C14: =12500 -> 12500 | D14: =C16 -> 12500 | E14: =D16 -> 12500 | F14: =E16 -> 12500 | G14: =F16 -> 12500 | H14: =G16 -> 12500
A15: Repayment | C15: =MAX(0,MIN('Projected Financials (Best Case'!C35,B14)) -> 0 | D15: =MAX(0,MIN('Projected Financials (Best Case'!D35,C14)) -> 0 | E15: =MAX(0,MIN('Projected Financials (Best Case'!E35,D14)) -> 0 | F15: =MAX(0,MIN('Projected Financials (Best Case'!F35,E14)) -> 0 | G15: =MAX(0,MIN('Projected Financials (Best Case'!G35,F14)) -> 0 | H15: =MAX(0,MIN('Projected Financials (Best Case'!H35,G14)) -> 12.692998
A16: Ending Balance | C16: =C14-C15 -> 12500 | D16: =D14-D15 -> 12500 | E16: =E14-E15 -> 12500 | F16: =F14-F15 -> 12500 | G16: =G14-G15 -> 12500 | H16: =H14-H15 -> 12487.307
A17: Interest | C17: =C14*5.52% -> 690 | D17: =D14*5.52% -> 690 | E17: =E14*5.52% -> 690 | F17: =F14*5.52% -> 690 | G17: =G14*5.52% -> 690 | H17: =H14*5.52% -> 690
A19: Total Interest | C19: =C7+C12+C17 -> 1750 | D19: =D7+D12+D17 -> 1750 | E19: =E7+E12+E17 -> 1750 | F19: =F7+F12+F17 -> 1750 | G19: =G7+G12+G17 -> 1750 | H19: =H7+H12+H17 -> 1750

Sheet Return Analysis
A1: Return Analysis
A2: Years | B2: 2022 | C2: 2023 | D2: 2024 | E2: 2025 | F2: 2026 | G2: 2027
A4: EBITDA | G4: ='Projected Financials (Best Case'!H20 -> 3191.4456
A5: Exit Multiple | G5: 25
A6: Enterprise Value | G6: =G4*G5 -> 79786.14
A7: Less: Debt | G7: 24148.781
A8: Plus: Cash | G8: 0
A9: Equity Value | G9: =G6-G7 -> 55637.359
