Workbook

Sheet Financials
B1: 1 | C1: 2 | D1: 3 | E1: 4 | F1: 5 | G1: 6 | H1: 7 | I1: 8 | J1: 9 | K1: 10 | L1: 11 | M1: 12
A2: United Health Income Statement - 10K
B3: 2014 | C3: 2015 | D3: 2016 | E3: 2017 | F3: 2018 | G3: 2019 | H3: 2020 | I3: 2021 | J3: 2022 | K3: 2023 | L3: 2024 | M3: 2025 | N3: 2026 | O3: 2027 | P3: 2028 | Q3: 2029 | R3: 2030 | S3: 2031 | T3: 2032 | U3: 2033 | V3: 2034
A4: Total revenues | B4: 130474 | C4: 157107 | D4: 184840 | E4: 201159 | F4: 226247 | G4: 242155 | H4: 257141 | I4: 287597 | J4: 324162 | K4: 371622 | L4: 400278 | M4: =FS_Forecast!M4 -> 447567 | N4: 439000 | O4: =N4*(1+O5) -> 445083.98 | P4: =O4*(1+P5) -> 465940.05 | Q4: =P4*(1+Q5) -> 503149.44 | R4: =Q4*(1+R5) -> 540542.86 | S4: =R4*(1+S5) -> 577720.72 | T4: =S4*(1+T5) -> 614255.04 | U4: =T4*(1+U5) -> 649696.78 | V4: =U4*(1+V5) -> 683545.98
A5: % increase in revenue | B5: -% | C5: =(C4/B4)-1 -> 0.20412496 | D5: =(D4/C4)-1 -> 0.17652301 | E5: =(E4/D4)-1 -> 0.088287167 | F5: =(F4/E4)-1 -> 0.12471726 | G5: =(G4/F4)-1 -> 0.070312535 | H5: =(H4/G4)-1 -> 0.061885982 | I5: =(I4/H4)-1 -> 0.11844086 | J5: =(J4/I4)-1 -> 0.12713971 | ... N5: =(N4/M4)-1 -> -0.019141268 | O5: =N5+3.3% -> 0.013858732 | P5: =O5+3.3% -> 0.046858732 | Q5: =P5+3.3% -> 0.079858732 | R5: =Q5-R6 -> 0.074318732 | S5: =R5-R6 -> 0.068778732 | T5: =S5-R6 -> 0.063238732 | U5: =T5-R6 -> 0.057698732 | V5: 0.0521
D6: 1 | E6: 2 | F6: 3 | I6: 4 | J6: 5 | K6: 6 | L6: 7 | R6: =2.77/500 -> 0.00554
A7: Total Cost Of Goods Sold | B7: =FS_Forecast!B7 -> 118722 | C7: =FS_Forecast!C7 -> 146068 | D7: =FS_Forecast!D7 -> 171910 | E7: =FS_Forecast!E7 -> 185950 | F7: =FS_Forecast!F7 -> 208903 | G7: =FS_Forecast!G7 -> 222470 | H7: =FS_Forecast!H7 -> 234736 | I7: =FS_Forecast!I7 -> 260524 | ... M7: =FS_Forecast!M7 -> 424242 | N7: 399182.7 | O7: 404686 | P7: 423619.81 | Q7: 457418.91 | R7: 491380.63 | S7: 525141.63 | T7: 558312.94 | U7: 590486.52 | V7: 621250.87
A8: % of total revenue | B8: =B7/B4 -> 0.90992841 | C8: =C7/C4 -> 0.92973579 | D8: =D7/D4 -> 0.93004761 | E8: =E7/E4 -> 0.92439314 | F8: =F7/F4 -> 0.92334042 | G8: =G7/G4 -> 0.91870909 | H8: =H7/H4 -> 0.91286882 | I8: =I7/I4 -> 0.9058648 | ... L8: =L7/L4 -> 0.91933856 | M8: =FS_Forecast!M8 -> 0.9478849 | N8: 0.9093 | O8: 0.9093 | P8: 0.9093 | Q8: 0.9093 | R8: 0.9093 | S8: 0.9093 | T8: 0.9093 | U8: 0.9093 | V8: 0.9093 | Y8: Total Cost Of Goods Sold | Z8: 118722 | AA8: 144393 | AB8: 169855 | AC8: 183705 | AD8: 206475 | AE8: 219750 | AF8: 231845 | AG8: 260524 | AH8: 292327 | AI8: 335292 | AJ8: 363892 | AK8: 406985.27 | AL8: 399182.7 | AM8: 404686 | AN8: 423619.81 | AO8: 457418.91 | AP8: 491380.63 | AQ8: 525141.63 | AR8: 558312.94 | AS8: 590486.52 | AT8: 621250.87
A9: Gross Profit | B9: =B4-B7 -> 11752 | C9: =C4-C7 -> 11039 | D9: =D4-D7 -> 12930 | E9: =E4-E7 -> 15209 | F9: =F4-F7 -> 17344 | G9: =G4-G7 -> 19685 | H9: =H4-H7 -> 22405 | I9: =I4-I7 -> 27073 | ... V9: =V4-V7 -> 62295.114 | Y9: % of total revenue | Z9: 0.90992841 | AA9: 0.91907426 | AB9: 0.91892989 | AC9: 0.91323282 | AD9: 0.91260879 | AE9: 0.90747662 | AF9: 0.90162596 | AG9: 0.9058648 | AH9: 0.90179293 | AI9: 0.90223937 | AJ9: 0.90909818 | AK9: 0.90926109 | AL9: 0.9093 | AM9: 0.9093 | AN9: 0.9093 | AO9: 0.9093 | AP9: 0.9093 | AQ9: 0.9093 | AR9: 0.9093 | AS9: 0.9093 | AT9: 0.9093
A10: % of total revenue | B10: =B9/B4 -> 0.090071585 | C10: =C9/C4 -> 0.070264215 | D10: =D9/D4 -> 0.069952391 | E10: =E9/E4 -> 0.075606858 | F10: =F9/F4 -> 0.07665958 | G10: =G9/G4 -> 0.081290909 | H10: =H9/H4 -> 0.087131185 | I10: =I9/I4 -> 0.094135196 | ... L10: =L9/L4 -> 0.08066144 | M10: =FS_Forecast!M10 -> 0.052115102 | N10: =N9/N4 -> 0.0907 | O10: =O9/O4 -> 0.090764857 | P10: =P9/P4 -> 0.090827666 | Q10: =Q9/Q4 -> 0.090888551 | R10: =R9/R4 -> 0.090949746 | S10: =S9/S4 -> 0.091011253 | T10: =T9/T4 -> 0.091073078 | U10: =U9/U4 -> 0.091135221 | V10: =V9/V4 -> 0.091135221 | Y10: Gross Profit | Z10: 11752 | AA10: 12714 | AB10: 14985 | AC10: 17454 | AD10: 19772 | AE10: 22405 | AF10: 25296 | AG10: 27073 | AH10: 31835 | AI10: 36330 | AJ10: 36386 | AK10: 40614.735 | AL10: 39817.3 | AM10: 40366.238 | AN10: 42254.829 | AO10: 45626.191 | AP10: 49013.772 | AQ10: 52381.333 | AR10: 55690.074 | AS10: 58899.293 | AT10: 61967.946
A11: Depreciation and amortization | B11: =H311 -> 1478 | C11: =I311 -> 1693 | D11: =B311 -> 2055 | E11: =C311 -> 2245 | F11: =D311 -> 2428 | G11: 2720 | H11: 2891 | I11: 3103 | J11: 3400 | K11: 3972 | L11: 4099 | M11: =FS_Forecast!M11 -> 4361 | N11: =N4*N12 -> 4785.1 | O11: =O4*O12 -> 4851.4154 | P11: =P4*P12 -> 5078.7466 | Q11: =Q4*Q12 -> 5484.3289 | R11: =R4*R12 -> 5891.9172 | S11: =S4*S12 -> 6297.1558 | T11: =T4*T12 -> 6695.38 | U11: =U4*U12 -> 7081.6949 | V11: =V4*V12 -> 7450.6512 | Y11: % of total revenue | Z11: 0.090071585 | AA11: 0.080925739 | AB11: 0.081070115 | AC11: 0.086767184 | AD11: 0.087391214 | AE11: 0.092523384 | AF11: 0.098374044 | AG11: 0.094135196 | AH11: 0.098207069 | AI11: 0.097760628 | AJ11: 0.090901823 | AK11: 0.090738907 | AL11: 0.0907 | AM11: 0.0907 | AN11: 0.0907 | AO11: 0.0907 | AP11: 0.0907 | AQ11: 0.0907 | AR11: 0.0907 | AS11: 0.0907 | AT11: 0.0907
A12: =A10 -> % of total revenue | B12: =B11/B4 -> 0.011327927 | C12: =C11/C4 -> 0.010776095 | D12: =D11/D4 -> 0.011117723 | E12: =E11/E4 -> 0.011160326 | F12: =F11/F4 -> 0.010731634 | G12: =G11/G4 -> 0.011232475 | H12: =H11/H4 -> 0.011242859 | I12: =I11/I4 -> 0.010789403 | ... L12: =L11/L4 -> 0.010240383 | M12: =FS_Forecast!M12 -> 0.0097437925 | N12: 0.0109 | O12: 0.0109 | P12: 0.0109 | Q12: 0.0109 | R12: 0.0109 | S12: 0.0109 | T12: 0.0109 | U12: 0.0109 | V12: 0.0109 | Y12: Depreciation and amortization | Z12: 1478 | AA12: 1693 | AB12: 2055 | AC12: 2245 | AD12: 2428 | AE12: 2720 | AF12: 2891 | AG12: 3103 | AH12: 3400 | AI12: 3972 | AJ12: 4099 | AK12: 4874.5955 | AL12: 4785.1 | AM12: 4851.0694 | AN12: 5078.0335 | AO12: 5483.1916 | AP12: 5890.299 | AQ12: 6295.0003 | AR12: 6692.6329 | AS12: 7078.3054 | AT12: 7447.0851
A13: EBIT | B13: =B9-B11 -> 10274 | C13: =C9-C11 -> 9346 | D13: =D9-D11 -> 10875 | E13: =E9-E11 -> 12964 | F13: =F9-F11 -> 14916 | G13: =G9-G11 -> 16965 | H13: =H9-H11 -> 19514 | I13: =I9-I11 -> 23970 | ... V13: =V9-V11 -> 54844.463 | Y13: % of total revenue | Z13: 0.011327927 | AA13: 0.010776095 | AB13: 0.011117723 | AC13: 0.011160326 | AD13: 0.010731634 | AE13: 0.011232475 | AF13: 0.011242859 | AG13: 0.010789403 | AH13: 0.010488583 | AI13: 0.01068828 | AJ13: 0.010240383 | AK13: 0.010890517 | AL13: 0.0109 | AM13: 0.0109 | AN13: 0.0109 | AO13: 0.0109 | AP13: 0.0109 | AQ13: 0.0109 | AR13: 0.0109 | AS13: 0.0109 | AT13: 0.0109
A14: % of total revenue | B14: =B13/B4 -> 0.078743658 | C14: =C13/C4 -> 0.05948812 | D14: =D13/D4 -> 0.058834668 | E14: =E13/E4 -> 0.064446532 | F14: =F13/F4 -> 0.065927946 | G14: =G13/G4 -> 0.070058434 | H14: =H13/H4 -> 0.075888326 | I14: =I13/I4 -> 0.083345793 | ... L14: =L13/L4 -> 0.070421057 | M14: =FS_Forecast!M14 -> 0.04237131 | N14: =N13/N4 -> 0.0798 | O14: =O13/O4 -> 0.079864857 | P14: =P13/P4 -> 0.079927666 | Q14: =Q13/Q4 -> 0.079988551 | R14: =R13/R4 -> 0.080049746 | S14: =S13/S4 -> 0.080111253 | T14: =T13/T4 -> 0.080173078 | U14: =U13/U4 -> 0.080235221 | V14: =V13/V4 -> 0.080235221 | Y14: EBIT | Z14: 10274 | AA14: 11021 | AB14: 12930 | AC14: 15209 | AD14: 17344 | AE14: 19685 | AF14: 22405 | AG14: 23970 | AH14: 28435 | AI14: 32358 | AJ14: 32287 | AK14: 35740.139 | AL14: 35032.2 | AM14: 35515.168 | AN14: 37176.796 | AO14: 40142.999 | AP14: 43123.473 | AQ14: 46086.332 | AR14: 48997.441 | AS14: 51820.988 | AT14: 54520.861
A15: Interest expense | B15: =H315 -> -618 | C15: =I315 -> -790 | D15: =B315 -> -1067 | E15: =C315 -> -1186 | F15: =D315 -> -1400 | G15: -1704 | H15: -1663 | I15: -1660 | J15: -2092 | K15: -3246 | L15: -3906 | M15: =FS_Forecast!M15 -> -4002 | N15: =-N4*N16 -> -4390 | O15: =-O4*O16 -> -4450.8398 | P15: =-P4*P16 -> -4659.4005 | Q15: =-Q4*Q16 -> -5031.4944 | R15: =-R4*R16 -> -5405.4286 | S15: =-S4*S16 -> -5777.2072 | T15: =-T4*T16 -> -6142.5504 | U15: =-U4*U16 -> -6496.9678 | V15: =-V4*V16 -> -6835.4598 | Y15: % of total revenue | Z15: 0.078743658 | AA15: 0.070149643 | AB15: 0.069952391 | AC15: 0.075606858 | AD15: 0.07665958 | AE15: 0.081290909 | AF15: 0.087131185 | AG15: 0.083345793 | AH15: 0.087718486 | AI15: 0.087072348 | AJ15: 0.08066144 | AK15: 0.07984839 | AL15: 0.0798 | AM15: 0.0798 | AN15: 0.0798 | AO15: 0.0798 | AP15: 0.0798 | AQ15: 0.0798 | AR15: 0.0798 | AS15: 0.0798 | AT15: 0.0798
A16: % of total revenue | B16: =-B15/B4 -> 0.0047365759 | C16: =-C15/C4 -> 0.0050284201 | D16: =-D15/D4 -> 0.0057725601 | E16: =-E15/E4 -> 0.0058958336 | F16: =-F15/F4 -> 0.0061879274 | G16: =-G15/G4 -> 0.0070368153 | H16: =-H15/H4 -> 0.0064672689 | I16: =-I15/I4 -> 0.0057719656 | ... L16: =-L15/L4 -> 0.009758218 | M16: =FS_Forecast!M16 -> 0.008941678 | N16: 0.01 | O16: 0.01 | P16: 0.01 | Q16: 0.01 | R16: 0.01 | S16: 0.01 | T16: 0.01 | U16: 0.01 | V16: 0.01 | Y16: Interest expense | Z16: -618 | AA16: -790 | AB16: -1067 | AC16: -1186 | AD16: -1400 | AE16: -1704 | AF16: -1663 | AG16: -1660 | AH16: -2092 | AI16: -3246 | AJ16: -3906 | AK16: -4476 | AL16: -4390 | AM16: -4450.5224 | AN16: -4658.7464 | AO16: -5030.451 | AP16: -5403.944 | AQ16: -5775.2296 | AR16: -6140.0302 | AS16: -6493.8581 | AT16: -6832.1881
A17: Loss on sale of subsidiary and subsidiaries held for sale | B17: 0 | C17: 0 | D17: 0 | E17: 0 | F17: 0 | G17: 0 | H17: 0 | I17: 0 | J17: 0 | K17: 0 | L17: -8310 | M17: =FS_Forecast!M17 -> 0 | N17: 0 | O17: 0 | P17: 0 | Q17: 0 | R17: 0 | S17: 0 | T17: 0 | U17: 0 | V17: 0 | Y17: % of total revenue | Z17: 0.0047365759 | AA17: 0.0050284201 | AB17: 0.0057725601 | AC17: 0.0058958336 | AD17: 0.0061879274 | AE17: 0.0070368153 | AF17: 0.0064672689 | AG17: 0.0057719656 | AH17: 0.0064535633 | AI17: 0.008734682 | AJ17: 0.009758218 | AK17: 0.01 | AL17: 0.01 | AM17: 0.01 | AN17: 0.01 | AO17: 0.01 | AP17: 0.01 | AQ17: 0.01 | AR17: 0.01 | AS17: 0.01 | AT17: 0.01
A18: Earnings Before Tax | B18: =SUM(B13,B15,B17) -> 9656 | C18: =SUM(C13,C15,C17) -> 8556 | D18: =SUM(D13,D15,D17) -> 9808 | E18: =SUM(E13,E15,E17) -> 11778 | F18: =SUM(F13,F15,F17) -> 13516 | G18: =SUM(G13,G15,G17) -> 15261 | H18: =SUM(H13,H15,H17) -> 17851 | I18: =SUM(I13,I15,I17) -> 22310 | ... V18: =SUM(V13,V15,V17) -> 48009.003 | Y18: Loss on sale of subsidiary and subsidiaries held for sale | Z18: 0 | AA18: 0 | AB18: 0 | AC18: 0 | AD18: 0 | AE18: 0 | AF18: 0 | AG18: 0 | AH18: 0 | AI18: 0 | AJ18: -8310 | AK18: 0 | AL18: 0 | AM18: 0 | AN18: 0 | AO18: 0 | AP18: 0 | AQ18: 0 | AR18: 0 | AS18: 0 | AT18: 0
A19: % of total revenue | B19: =B18/B4 -> 0.074007082 | C19: =C18/C4 -> 0.054459699 | D19: =D18/D4 -> 0.053062108 | E19: =E18/E4 -> 0.058550699 | F19: =F18/F4 -> 0.059740019 | G19: =G18/G4 -> 0.063021618 | H19: =H18/H4 -> 0.069421057 | I19: =I18/I4 -> 0.077573827 | ... L19: =L18/L4 -> 0.039902268 | M19: =FS_Forecast!M19 -> 0.033429632 | N19: =N18/N4 -> 0.0698 | O19: =O18/O4 -> 0.069864857 | P19: =P18/P4 -> 0.069927666 | Q19: =Q18/Q4 -> 0.069988551 | R19: =R18/R4 -> 0.070049746 | S19: =S18/S4 -> 0.070111253 | T19: =T18/T4 -> 0.070173078 | U19: =U18/U4 -> 0.070235221 | V19: =V18/V4 -> 0.070235221 | Y19: Earnings Before Tax | Z19: 9656 | AA19: 10231 | AB19: 11863 | AC19: 14023 | AD19: 15944 | AE19: 17981 | AF19: 20742 | AG19: 22310 | AH19: 26343 | AI19: 29112 | AJ19: 20071 | AK19: 31264.139 | AL19: 30642.2 | AM19: 31064.646 | AN19: 32518.05 | AO19: 35112.548 | AP19: 37719.529 | AQ19: 40311.103 | AR19: 42857.411 | AS19: 45327.13 | AT19: 47688.673
A20: Provision for income taxes | B20: =H317 -> -4037 | C20: =I317 -> -4363 | D20: =B317 -> -4790 | E20: =C317 -> -3200 | F20: =D317 -> -3562 | G20: -3742 | H20: -4973 | I20: -4578 | J20: -4829 | K20: -5968 | L20: -5704 | M20: =FS_Forecast!M20 -> -1890 | N20: =-N21*N13 -> -6190.1897 | O20: =-O21*O13 -> -6281.0787 | P20: =-P21*P13 -> -6580.5732 | Q20: =-Q21*Q13 -> -7111.5025 | R20: =-R21*R13 -> -7645.8653 | S20: =-S21*S13 -> -8178.0172 | T20: =-T21*T13 -> -8701.8949 | U20: =-U21*U13 -> -9211.1174 | V20: =-V21*V13 -> -9691.0166 | Y20: % of total revenue | Z20: 0.074007082 | AA20: 0.065121223 | AB20: 0.064179831 | AC20: 0.069711025 | AD20: 0.070471653 | AE20: 0.074254093 | AF20: 0.080663916 | AG20: 0.077573827 | AH20: 0.081264923 | AI20: 0.078337666 | AJ20: 0.050142651 | AK20: 0.06984839 | AL20: 0.0698 | AM20: 0.0698 | AN20: 0.0698 | AO20: 0.0698 | AP20: 0.0698 | AQ20: 0.0698 | AR20: 0.0698 | AS20: 0.0698 | AT20: 0.0698
A21: Net Income | B21: =-B20/B13 -> 0.39293362 | C21: =-C20/C13 -> 0.46683073 | D21: =-D20/D13 -> 0.44045977 | E21: =-E20/E13 -> 0.2468374 | F21: =-F20/F13 -> 0.23880397 | G21: =-G20/G13 -> 0.22057177 | H21: =-H20/H13 -> 0.25484268 | I21: =-I20/I13 -> 0.19098874 | ... L21: =-L20/L13 -> 0.20235561 | M21: =FS_Forecast!M21 -> 0.12632001 | N21: 0.1767 | O21: 0.1767 | P21: 0.1767 | Q21: 0.1767 | R21: 0.1767 | S21: 0.1767 | T21: 0.1767 | U21: 0.1767 | V21: 0.1767 | Y21: Provision for income taxes | Z21: -4037 | AA21: -4363 | AB21: -4790 | AC21: -3200 | AD21: -3562 | AE21: -3742 | AF21: -4973 | AG21: -4578 | AH21: -4829 | AI21: -5968 | AJ21: -5704 | AK21: -6315.2826 | AL21: -6190.1897 | AM21: -6275.5303 | AN21: -6569.1398 | AO21: -7093.268 | AP21: -7619.9177 | AQ21: -8143.4549 | AR21: -8657.8478 | AS21: -9156.7685 | AT21: -9633.8362
A22: Net Income | B22: =B18+B20 -> 5619 | C22: =C18+C20 -> 4193 | D22: =D18+D20 -> 5018 | E22: =E18+E20 -> 8578 | F22: =F18+F20 -> 9954 | G22: =G18+G20 -> 11519 | H22: =H18+H20 -> 12878 | I22: =I18+I20 -> 17732 | ... V22: =V18+V20 -> 38317.987 | Y22: Net Income | Z22: 0.39293362 | AA22: 0.39588059 | AB22: 0.3704563 | AC22: 0.21040174 | AD22: 0.20537362 | AE22: 0.19009398 | AF22: 0.22195938 | AG22: 0.19098874 | AH22: 0.16982592 | AI22: 0.18443662 | AJ22: 0.17666553 | AK22: 0.1767 | AL22: 0.1767 | AM22: 0.1767 | AN22: 0.1767 | AO22: 0.1767 | AP22: 0.1767 | AQ22: 0.1767 | AR22: 0.1767 | AS22: 0.1767 | AT22: 0.1767
B23: =B22/B4 -> 0.043066051 | C23: =C22/C4 -> 0.026688817 | D23: =D22/D4 -> 0.027147804 | E23: =E22/E4 -> 0.042642884 | F23: =F22/F4 -> 0.043996163 | G23: =G22/G4 -> 0.047568706 | H23: =H22/H4 -> 0.050081473 | I23: =I22/I4 -> 0.06165572 | ... L23: =L22/L4 -> 0.025652172 | M23: =FS_Forecast!M23 -> 0.0292068 | N23: =N22/N4 -> 0.05569934 | O23: =O22/O4 -> 0.055752737 | P23: =P22/P4 -> 0.055804447 | Q23: =Q22/Q4 -> 0.055854574 | R23: =R22/R4 -> 0.055904956 | S23: =S22/S4 -> 0.055955595 | T23: =T22/T4 -> 0.056006495 | U23: =U22/U4 -> 0.056057658 | V23: =V22/V4 -> 0.056057658 | Y23: Net Income | Z23: 5619 | AA23: 5868 | AB23: 7073 | AC23: 10823 | AD23: 12382 | AE23: 14239 | AF23: 15769 | AG23: 17732 | AH23: 21514 | AI23: 23144 | AJ23: 14367 | AK23: 24948.857 | AL23: 24452.01 | AM23: 24789.116 | AN23: 25948.91 | AO23: 28019.28 | AP23: 30099.611 | AQ23: 32167.648 | AR23: 34199.563 | AS23: 36170.361 | AT23: 38054.837
Z24: 0.043066051 | AA24: 0.037350341 | AB24: 0.038265527 | AC24: 0.05380321 | AD24: 0.054727797 | AE24: 0.058801181 | AF24: 0.061324332 | AG24: 0.06165572 | AH24: 0.066368051 | AI24: 0.062278337 | AJ24: 0.035892555 | AK24: 0.05573918 | AL24: 0.05569934 | AM24: 0.05569934 | AN24: 0.05569934 | AO24: 0.05569934 | AP24: 0.05569934 | AQ24: 0.05569934 | AR24: 0.05569934 | AS24: 0.05569934 | AT24: 0.05569934
B25: 1 | C25: 2 | D25: 3 | E25: 4 | F25: 5 | G25: 6 | H25: 7 | I25: 8 | J25: 9 | K25: 10 | L25: 11
A26: United Health Balance Sheet - 10K
B27: 2014 | C27: 2015 | D27: 2016 | E27: 2017 | F27: 2018 | G27: 2019 | H27: 2020 | I27: 2021 | J27: 2022 | K27: 2023 | L27: 2024 | M27: 2025(UA) | N27: 2026 | O27: 2027 | P27: 2028 | Q27: 2029 | R27: 2030 | S27: 2031 | T27: 2032
A28: Current assets:
A29: Cash and cash equivalents | B29: 7495 | C29: 10923 | D29: 10430 | E29: 11981 | F29: 10866 | G29: 10985 | H29: 16921 | I29: 21375 | J29: 23365 | K29: 25427 | L29: 25312 | M29: =FS_Forecast!M46 -> 24365
A31: Short-term investments | B31: 1741 | C31: 1988 | D31: 2845 | E31: 3509 | F31: 3458 | G31: 3260 | H31: 2860 | I31: 2532 | J31: 4546 | K31: 4201 | L31: 3801 | M31: 3801
A33: Accounts receivable, net | B33: 4252 | C33: 6523 | D33: 8152 | E33: 9568 | F33: 11388 | G33: 11822 | H33: 12870 | I33: 14216 | J33: 17681 | K33: 21276 | L33: 22365 | M33: 23018 | N33: =N34*FS_Forecast!N4 -> 22646.501 | O33: =O34*FS_Forecast!O4 -> 22958.715 | P33: =P34*FS_Forecast!P4 -> 23463.495 | Q33: =Q34*FS_Forecast!Q4 -> 24171.773 | R33: =R34*FS_Forecast!R4 -> 25099.641 | S33: =S34*FS_Forecast!S4 -> 26268.943 | T33: =T34*FS_Forecast!T4 -> 27713.735
A34: Account Receivables/Revenue | B34: =B33/B4 -> 0.032588868 | C34: =C33/C4 -> 0.041519474 | D34: =D33/D4 -> 0.044103008 | E34: =E33/E4 -> 0.047564365 | F34: =F33/F4 -> 0.050334369 | G34: =G33/G4 -> 0.048819971 | H34: =H33/H4 -> 0.050050361 | I34: =I33/I4 -> 0.049430279 | ... L34: =L33/L4 -> 0.055873668 | M34: =M33/FS_Forecast!M4 -> 0.051429172 | N34: =IFERROR(__xludf.DUMMYFUNCTION("AVERAGE.WEIGHTED(B34:M34,B1:M1)"),0.05158656170130325) -> 0.051586562 | O34: =N34 -> 0.051586562 | P34: =O34 -> 0.051586562 | Q34: =P34 -> 0.051586562 | R34: =Q34 -> 0.051586562 | S34: =R34 -> 0.051586562 | T34: =S34 -> 0.051586562
A35: Other current receivables, net | B35: 5498 | C35: 6801 | D35: 7499 | E35: 6262 | F35: 6862 | G35: 9640 | H35: 12534 | I35: 13866 | J35: 12769 | K35: 17694 | L35: 26089 | M35: 29697 | N35: =N36*FS_Forecast!N4 -> 29128.562 | O35: =O36*FS_Forecast!O4 -> 29530.14 | P35: =P36*FS_Forecast!P4 -> 30179.402 | Q35: =Q36*FS_Forecast!Q4 -> 31090.41 | R35: =R36*FS_Forecast!R4 -> 32283.86 | S35: =S36*FS_Forecast!S4 -> 33787.849 | T35: =T36*FS_Forecast!T4 -> 35646.181
A36: Other Receivables/Revenue | B36: =B35/B4 -> 0.042138664 | C36: =C35/C4 -> 0.043288969 | D36: =D35/D4 -> 0.040570223 | E36: =E35/E4 -> 0.031129604 | F36: =F35/F4 -> 0.030329684 | G36: =G35/G4 -> 0.039809213 | H36: =H35/H4 -> 0.048743685 | I36: =I35/I4 -> 0.048213298 | ... L36: =L35/L4 -> 0.065177202 | M36: =M35/FS_Forecast!M4 -> 0.066352077 | N36: =M36 -> 0.066352077 | O36: =N36 -> 0.066352077 | P36: =O36 -> 0.066352077 | Q36: =P36 -> 0.066352077 | R36: =Q36 -> 0.066352077 | S36: =R36 -> 0.066352077 | T36: =S36 -> 0.066352077
A37: Assets under management | B37: 2962 | C37: 2998 | D37: 3105 | E37: 3101 | F37: 3032 | G37: 3076 | H37: 4076 | I37: 4449 | J37: 4087 | K37: 3755 | L37: - | M37: - | N37: - | O37: - | P37: - | Q37: - | R37: - | S37: - | T37: -
A38: Deferred income taxes (current) | B38: 556 | C38: 860 | D38: - | E38: - | F38: - | G38: - | H38: - | I38: - | J38: - | K38: - | L38: - | M38: - | N38: - | O38: - | P38: - | Q38: - | R38: - | S38: - | T38: -
A39: Prepaid expenses and other current assets | B39: 1052 | C39: 1546 | D39: 1848 | E39: 2663 | F39: 3086 | G39: 3851 | H39: 4457 | I39: 5320 | J39: 6621 | K39: 6084 | L39: 8212 | M39: 9746 | N39: =N40*FS_Forecast!N4 -> 7756.4681 | O39: =O40*FS_Forecast!O4 -> 7863.402 | P39: =P40*FS_Forecast!P4 -> 8036.29 | Q39: =Q40*FS_Forecast!Q4 -> 8278.8768 | R39: =R40*FS_Forecast!R4 -> 8596.6732 | S39: =S40*FS_Forecast!S4 -> 8997.1614 | T39: =T40*FS_Forecast!T4 -> 9492.0053
A40: Prepaid Exp/Revenue | B40: =B39/B4 -> 0.0080629091 | C40: =C39/C4 -> 0.0098404272 | D40: =D39/D4 -> 0.009997836 | E40: =E39/E4 -> 0.013238284 | F40: =F39/F4 -> 0.01363996 | G40: =G39/G4 -> 0.015903037 | H40: =H39/H4 -> 0.017332903 | I40: =I39/I4 -> 0.018498107 | ... L40: =L39/L4 -> 0.020515742 | M40: =M39/FS_Forecast!M4 -> 0.021775511 | N40: =IFERROR(__xludf.DUMMYFUNCTION("AVERAGE.WEIGHTED(B40:M40,B1:M1)"),0.017668492154409552) -> 0.017668492 | O40: =N40 -> 0.017668492 | P40: =O40 -> 0.017668492 | Q40: =P40 -> 0.017668492 | R40: =Q40 -> 0.017668492 | S40: =R40 -> 0.017668492 | T40: =S40 -> 0.017668492
A41: Total current assets | B41: 23556 | C41: 31639 | D41: 33879 | E41: 37084 | F41: 38692 | G41: 42634 | H41: 53718 | I41: 61758 | J41: 69069 | K41: 78437 | L41: 85779 | M41: =SUM(M33+M35+M39) -> 62461 | N41: =SUM(N33+N35+N39) -> 59531.53 | O41: =SUM(O33+O35+O39) -> 60352.257 | P41: =SUM(P33+P35+P39) -> 61679.187 | Q41: =SUM(Q33+Q35+Q39) -> 63541.06 | R41: =SUM(R33+R35+R39) -> 65980.174 | S41: =SUM(S33+S35+S39) -> 69053.954 | T41: =SUM(T33+T35+T39) -> 72851.921
A42: Long-term investments | B42: 18827 | C42: 18792 | D42: 23868 | E42: 28341 | F42: 32510 | G42: 37209 | H42: 41242 | I42: 43114 | J42: 43728 | K42: 47609 | L42: 52354 | M42: 54251
...

Sheet FS_Forecast
B1: 1 | C1: 2 | D1: 3 | E1: 4 | F1: 5 | G1: 6 | H1: 7 | I1: 8 | J1: 9 | K1: 10 | L1: 11 | M1: 12 | N1: 13
B2: United Health Income Statement - Actuals | N2: Forecasts
B3: 2014 | C3: 2015 | D3: 2016 | E3: 2017 | F3: 2018 | G3: 2019 | H3: 2020 | I3: 2021 | J3: 2022 | K3: 2023 | L3: 2024 | M3: 2025(UA) | N3: 2026 | O3: 2027 | P3: 2028 | Q3: 2029 | R3: 2030 | S3: 2031 | T3: 2032
A4: Total revenues | B4: 130474 | C4: 157107 | D4: 184840 | E4: 201159 | F4: 226247 | G4: 242155 | H4: 257141 | I4: 287597 | J4: 324162 | K4: 371622 | L4: 400278 | M4: 447567 | N4: 439000 | O4: =N4*(1+O5) -> 445052.24 | P4: =O4*(1+P5) -> 454837.34 | Q4: =P4*(1+Q5) -> 468567.25 | R4: =Q4*(1+R5) -> 486553.87 | S4: =R4*(1+S5) -> 509220.67 | T4: =S4*(1+T5) -> 537227.81
A5: % increase in revenue | B5: -% | C5: 0.20412496 | D5: 0.17652301 | E5: 0.088287167 | F5: 0.12471726 | G5: 0.070312535 | H5: 0.061885982 | I5: 0.11844086 | J5: 0.12713971 | K5: 0.14640828 | L5: 0.077110612 | M5: 0.11822284 | N5: -0.019213584 | O5: 0.013786416 | P5: =O5+0.82% -> 0.021986416 | Q5: =P5+0.82% -> 0.030186416 | R5: =Q5+0.82% -> 0.038386416 | S5: =R5+0.82% -> 0.046586416 | T5: 0.055
D6: 1 | E6: 2 | F6: 3 | I6: 4 | J6: 5 | K6: 6 | L6: 7 | R6: 0.00554
A7: Total Cost Of Goods Sold | B7: 118722 | C7: 146068 | D7: 171910 | E7: 185950 | F7: 208903 | G7: 222470 | H7: 234736 | I7: 260524 | J7: 295727 | K7: 339264 | L7: 367991 | M7: =313995+59592+50655 -> 424242 | N7: =N4-N9 -> 410196.01 | O7: =O4*O8 -> 409962.86 | P7: =P4*P8 -> 418976.48 | Q7: =Q4*Q8 -> 431623.88 | R7: =R4*R8 -> 448192.37 | S7: =S4*S8 -> 469072.05 | T7: =T4*T8 -> 494871.01
A8: % of total revenue | B8: =B7/B4 -> 0.90992841 | C8: =C7/C4 -> 0.92973579 | D8: =D7/D4 -> 0.93004761 | E8: =E7/E4 -> 0.92439314 | F8: =F7/F4 -> 0.92334042 | G8: =G7/G4 -> 0.91870909 | H8: =H7/H4 -> 0.91286882 | I8: =I7/I4 -> 0.9058648 | ... M8: =M7/M4 -> 0.9478849 | N8: =IFERROR(__xludf.DUMMYFUNCTION("AVERAGE.WEIGHTED(B8:M8,B1:M1)"),0.921156733808051) -> 0.92115673 | O8: =IFERROR(__xludf.DUMMYFUNCTION("AVERAGE.WEIGHTED(B8:N8,B1:N1)"),0.921156733808051) -> 0.92115673 | P8: =O8 -> 0.92115673 | Q8: =P8 -> 0.92115673 | R8: =Q8 -> 0.92115673 | S8: =R8 -> 0.92115673 | T8: =S8 -> 0.92115673
A9: Gross Profit | B9: 11752 | C9: 12714 | D9: 14985 | E9: 17454 | F9: 19772 | G9: 22405 | H9: 25296 | I9: 27073 | J9: 31835 | K9: 36330 | L9: 36386 | M9: =M4-M7 -> 23325 | N9: =N13+N11 -> 28803.987 | O9: =O4-O7 -> 35089.372 | P9: =P4-P7 -> 35860.862 | Q9: =Q4-Q7 -> 36943.372 | R9: =R4-R7 -> 38361.496 | S9: =S4-S7 -> 40148.621 | T9: =T4-T7 -> 42356.795
A10: % of total revenue | B10: 0.090071585 | C10: 0.080925739 | D10: 0.081070115 | E10: 0.086767184 | F10: 0.087391214 | G10: 0.092523384 | H10: 0.098374044 | I10: 0.094135196 | J10: 0.098207069 | K10: 0.097760628 | L10: 0.090901823 | M10: =M9/M4 -> 0.052115102 | N10: =N9/N4 -> 0.065612726 | O10: =O9/O4 -> 0.078843266 | P10: =P9/P4 -> 0.078843266 | Q10: =Q9/Q4 -> 0.078843266 | R10: =R9/R4 -> 0.078843266 | S10: =S9/S4 -> 0.078843266 | T10: =T9/T4 -> 0.078843266
A11: Depreciation and amortization | B11: 1478 | C11: 1693 | D11: 2055 | E11: 2245 | F11: 2428 | G11: 2720 | H11: 2891 | I11: 3103 | J11: 3400 | K11: 3972 | L11: 4099 | M11: =M9-M13 -> 4361 | N11: =N12*N4 -> 4658.9867 | O11: =O12*O4 -> 4723.2174 | P11: =P12*P4 -> 4827.064 | Q11: =Q12*Q4 -> 4972.7758 | R11: =R12*R4 -> 5163.6628 | S11: =S12*S4 -> 5404.2194 | T11: =T12*T4 -> 5701.4514
A12: % of total revenue | B12: 0.011327927 | C12: 0.010776095 | D12: 0.011117723 | E12: 0.011160326 | F12: 0.010731634 | G12: 0.011232475 | H12: 0.011242859 | I12: 0.010789403 | J12: 0.010488583 | K12: 0.01068828 | L12: 0.010240383 | M12: =M11/M4 -> 0.0097437925 | N12: =IFERROR(__xludf.DUMMYFUNCTION("AVERAGE.WEIGHTED(B12:M12,B1:M1)"),0.010612725897022154) -> 0.010612726 | O12: =N12 -> 0.010612726 | P12: =O12 -> 0.010612726 | Q12: =P12 -> 0.010612726 | R12: =Q12 -> 0.010612726 | S12: =R12 -> 0.010612726 | T12: =S12 -> 0.010612726
A13: EBIT | B13: 10274 | C13: 11021 | D13: 12930 | E13: 15209 | F13: 17344 | G13: 19685 | H13: 22405 | I13: 23970 | J13: 28435 | K13: 32358 | L13: 32287 | M13: 18964 | N13: =N4*N14 -> 24145 | O13: =O9-O11 -> 30366.155 | P13: =P9-P11 -> 31033.798 | Q13: =Q9-Q11 -> 31970.597 | R13: =R9-R11 -> 33197.833 | S13: =S9-S11 -> 34744.401 | T13: =T9-T11 -> 36655.343
A14: % of total revenue | B14: 0.078743658 | C14: 0.070149643 | D14: 0.069952391 | E14: 0.075606858 | F14: 0.07665958 | G14: 0.081290909 | H14: 0.087131185 | I14: 0.083345793 | J14: 0.087718486 | K14: 0.087072348 | L14: 0.08066144 | M14: =M13/M4 -> 0.04237131 | N14: 0.055 | O14: =O13/O4 -> 0.06823054 | P14: =P13/P4 -> 0.06823054 | Q14: =Q13/Q4 -> 0.06823054 | R14: =R13/R4 -> 0.06823054 | S14: =S13/S4 -> 0.06823054 | T14: =T13/T4 -> 0.06823054
A15: Interest expense | B15: -618 | C15: -790 | D15: -1067 | E15: -1186 | F15: -1400 | G15: -1704 | H15: -1663 | I15: -1660 | J15: -2092 | K15: -3246 | L15: -3906 | M15: -4002 | N15: =-N16*N4 -> -3266.447 | O15: =-O16*O4 -> -3311.4796 | P15: =-P16*P4 -> -3384.2872 | Q15: =-Q16*Q4 -> -3486.4467 | R15: =-R16*R4 -> -3620.2789 | S15: =-S16*S4 -> -3788.9347 | T15: =-T16*T4 -> -3997.3261
A16: % of total revenue | B16: 0.0047365759 | C16: 0.0050284201 | D16: 0.0057725601 | E16: 0.0058958336 | F16: 0.0061879274 | G16: 0.0070368153 | H16: 0.0064672689 | I16: 0.0057719656 | J16: 0.0064535633 | K16: 0.008734682 | L16: 0.009758218 | M16: =-M15/M4 -> 0.008941678 | N16: =IFERROR(__xludf.DUMMYFUNCTION("AVERAGE.WEIGHTED(B16:M16,B1:M1)"),0.007440653737003448) -> 0.0074406537 | O16: =N16 -> 0.0074406537 | P16: =O16 -> 0.0074406537 | Q16: =P16 -> 0.0074406537 | R16: =Q16 -> 0.0074406537 | S16: =R16 -> 0.0074406537 | T16: =S16 -> 0.0074406537
A17: Loss on sale of subsidiary and subsidiaries held for sale | B17: 0 | C17: 0 | D17: 0 | E17: 0 | F17: 0 | G17: 0 | H17: 0 | I17: 0 | J17: 0 | K17: 0 | L17: -8310 | M17: 0 | N17: 0 | O17: 0 | P17: 0 | Q17: 0 | R17: 0 | S17: 0 | T17: 0
A18: Earnings Before Tax | B18: 9656 | C18: 10231 | D18: 11863 | E18: 14023 | F18: 15944 | G18: 17981 | H18: 20742 | I18: 22310 | J18: 26343 | K18: =K13+K15 -> 29112 | L18: 20071 | M18: =M13+M15 -> 14962 | N18: =N13+N15 -> 20878.553 | O18: =O13+O15 -> 27054.675 | P18: =P13+P15 -> 27649.51 | Q18: =Q13+Q15 -> 28484.15 | R18: =R13+R15 -> 29577.554 | S18: =S13+S15 -> 30955.467 | T18: =T13+T15 -> 32658.017
A19: % of total revenue | B19: 0.074007082 | C19: 0.065121223 | D19: 0.064179831 | E19: 0.069711025 | F19: 0.070471653 | G19: 0.074254093 | H19: 0.080663916 | I19: 0.077573827 | J19: 0.081264923 | K19: 0.078337666 | L19: 0.050142651 | M19: =M18/M4 -> 0.033429632 | N19: =N18/N4 -> 0.047559346 | O19: =O18/O4 -> 0.060789887 | P19: =P18/P4 -> 0.060789887 | Q19: =Q18/Q4 -> 0.060789887 | R19: =R18/R4 -> 0.060789887 | S19: =S18/S4 -> 0.060789887 | T19: =T18/T4 -> 0.060789887
A20: Provision for income taxes | B20: -4037 | C20: -4363 | D20: -4790 | E20: -3200 | F20: -3562 | G20: -3742 | H20: -4973 | I20: -4578 | J20: -4829 | K20: -5968 | L20: -4829 | M20: =-1890 -> -1890 | N20: =-N18*N21 -> -4880.2173 | O20: =-O18*O21 -> -6323.8431 | P20: =-P18*P21 -> -6462.8818 | Q20: =-Q18*Q21 -> -6657.973 | R20: =-R18*R21 -> -6913.5487 | S20: =-S18*S21 -> -7235.6262 | T20: =-T18*T21 -> -7633.5856
A21: tax rate | B21: =-B20/B18 -> 0.41808202 | C21: =-C20/C18 -> 0.42644903 | D21: =-D20/D18 -> 0.40377645 | E21: =-E20/E18 -> 0.22819653 | F21: =-F20/F18 -> 0.22340692 | G21: =-G20/G18 -> 0.20810856 | H21: =-H20/H18 -> 0.23975509 | I21: =-I20/I18 -> 0.20519946 | ... M21: =-M20/M18 -> 0.12632001 | N21: =IFERROR(__xludf.DUMMYFUNCTION("AVERAGE.WEIGHTED(B21:L21,B1:L1)"),0.23374308179355377) -> 0.23374308 | O21: =N21 -> 0.23374308 | P21: =O21 -> 0.23374308 | Q21: =P21 -> 0.23374308 | R21: =Q21 -> 0.23374308 | S21: =R21 -> 0.23374308 | T21: =S21 -> 0.23374308
A22: Net Income | B22: 5619 | C22: 5868 | D22: 7073 | E22: 10823 | F22: 12382 | G22: 14239 | H22: 15769 | I22: 17732 | J22: 21514 | K22: =K18*(1-K21) -> 23144 | L22: =L18*(1-L21) -> 15242 | M22: =M18*(1-M21) -> 13072 | N22: =N18*(1-N21) -> 15998.336 | O22: =O18+O20 -> 20730.832 | P22: =P18+P20 -> 21186.629 | Q22: =Q18+Q20 -> 21826.177 | R22: =R18+R20 -> 22664.006 | S22: =S18+S20 -> 23719.84 | T22: =T18+T20 -> 25024.432
B23: 0.043066051 | C23: 0.037350341 | D23: 0.038265527 | E23: 0.05380321 | F23: 0.054727797 | G23: 0.058801181 | H23: 0.061324332 | I23: 0.06165572 | J23: 0.066368051 | K23: 0.062278337 | L23: 0.035892555 | M23: =M22/M4 -> 0.0292068 | N23: =N22/N4 -> 0.036442678 | O23: =O22/O4 -> 0.046580671 | P23: =P22/P4 -> 0.046580671 | Q23: =Q22/Q4 -> 0.046580671 | R23: =R22/R4 -> 0.046580671 | S23: =S22/S4 -> 0.046580671 | T23: =T22/T4 -> 0.046580671
B27: Calculation Of Operating working Capital
B28: 2014 | C28: 2015 | D28: 2016 | E28: 2017 | F28: 2018 | G28: 2019 | H28: 2020 | I28: 2021 | J28: 2022 | K28: 2023 | L28: 2024 | M28: 2025 | N28: 2026 | O28: 2027 | P28: 2028 | Q28: 2029 | R28: 2030 | S28: 2031 | T28: 2032
A29: Operating Assets
A30: Accounts receivable, net | B30: =Financials!B33 -> 4252 | C30: =Financials!C33 -> 6523 | D30: =Financials!D33 -> 8152 | E30: =Financials!E33 -> 9568 | F30: =Financials!F33 -> 11388 | G30: =Financials!G33 -> 11822 | H30: =Financials!H33 -> 12870 | I30: =Financials!I33 -> 14216 | ... T30: =Financials!T33 -> 27713.735
A31: Other current receivables, net | B31: =Financials!B35 -> 5498 | C31: =Financials!C35 -> 6801 | D31: =Financials!D35 -> 7499 | E31: =Financials!E35 -> 6262 | F31: =Financials!F35 -> 6862 | G31: =Financials!G35 -> 9640 | H31: =Financials!H35 -> 12534 | I31: =Financials!I35 -> 13866 | ... T31: =Financials!T35 -> 35646.181
A32: Prepaid expenses and other current assets | B32: =Financials!B39 -> 1052 | C32: =Financials!C39 -> 1546 | D32: =Financials!D39 -> 1848 | E32: =Financials!E39 -> 2663 | F32: =Financials!F39 -> 3086 | G32: =Financials!G39 -> 3851 | H32: =Financials!H39 -> 4457 | I32: =Financials!I39 -> 5320 | ... T32: =Financials!T39 -> 9492.0053
A33: Total operating Assets | B33: =SUM(B30:B32) -> 10802 | C33: =SUM(C30:C32) -> 14870 | D33: =SUM(D30:D32) -> 17499 | E33: =SUM(E30:E32) -> 18493 | F33: =SUM(F30:F32) -> 21336 | G33: =SUM(G30:G32) -> 25313 | H33: =SUM(H30:H32) -> 29861 | I33: =SUM(I30:I32) -> 33402 | ... T33: =SUM(T30:T32) -> 72851.921
A34: Operating Liabilities
A35: =Financials!A56 -> Medical costs payable | B35: =Financials!B56 -> 14330 | C35: =Financials!C56 -> 14330 | D35: =Financials!D56 -> 16391 | E35: =Financials!E56 -> 17871 | F35: =Financials!F56 -> 19891 | G35: =Financials!G56 -> 21690 | H35: =Financials!H56 -> 21872 | ... T35: =Financials!T56 -> 47122.643
A36: =Financials!A58 -> Accounts payable and accrued liabilities | B36: =Financials!B58 -> 11994 | C36: =Financials!C58 -> 11994 | D36: =Financials!D58 -> 13361 | E36: =Financials!E58 -> 15180 | F36: =Financials!F58 -> 16705 | G36: =Financials!G58 -> 19005 | H36: =Financials!H58 -> 22495 | ... T36: =Financials!T58 -> 44813.783
A37: =Financials!A63 -> Other current liabilities | B37: 5965 | C37: 7798 | D37: =Financials!D63 -> 10339 | E37: =Financials!E63 -> 12286 | F37: =Financials!F63 -> 12244 | G37: =Financials!G63 -> 14595 | H37: =Financials!H63 -> 20392 | I37: =Financials!I63 -> 22975 | J37: =Financials!J63 -> 26281 | K37: =Financials!K63 -> 27072 | ... T37: =Financials!T63 -> 36814.698
A38: =Financials!A61 -> Unearned revenues | B38: =Financials!B61 -> 2142 | C38: =Financials!C61 -> 2142 | D38: =Financials!D61 -> 1968 | E38: =Financials!E61 -> 2269 | F38: =Financials!F61 -> 2396 | G38: =Financials!G61 -> 2622 | H38: =Financials!H61 -> 2842 | ... T38: =Financials!T61 -> 4297.8224
A39: Total Operating Liabilities | B39: =SUM(B35:B38) -> 34431 | C39: =SUM(C35:C38) -> 36264 | D39: =SUM(D35:D38) -> 42059 | E39: =SUM(E35:E38) -> 47606 | F39: =SUM(F35:F38) -> 51236 | G39: =SUM(G35:G38) -> 57912 | H39: =SUM(H35:H38) -> 67601 | I39: =SUM(I35:I38) -> 74672 | ... T39: =SUM(T35:T38) -> 133048.95
A40: Working Capital | B40: =B33-B39 -> -23629 | C40: =C33-C39 -> -21394 | D40: =D33-D39 -> -24560 | E40: =E33-E39 -> -29113 | F40: =F33-F39 -> -29900 | G40: =G33-G39 -> -32599 | H40: =H33-H39 -> -37740 | I40: =I33-I39 -> -41270 | ... T40: =T33-T39 -> -60197.025
A41: Change in NWC | C41: =C40-B40 -> 2235 | D41: =D40-C40 -> -3166 | E41: =E40-D40 -> -4553 | F41: =F40-E40 -> -787 | G41: =G40-F40 -> -2699 | H41: =H40-G40 -> -5141 | I41: =I40-H40 -> -3530 | J41: =J40-I40 -> -7786 | ... T41: =T40-S40 -> -3138.2335
A42: NWC/Revenue
B45: 2014 | C45: 2015 | D45: 2016 | E45: 2017 | F45: 2018 | G45: 2019 | H45: 2020 | I45: 2021 | J45: 2022 | K45: 2023 | L45: 2024 | M45: 2025
...

Sheet FCFF 
D2: Calculation Of Free Cash Flows
B3: 2015 | C3: 2016 | D3: 2017 | E3: 2018 | F3: 2019 | G3: 2020 | H3: 2021 | I3: 2022 | J3: 2023 | K3: 2024 | L3: 2025(UA) | M3: 2026 | N3: 2027 | O3: 2028 | P3: 2029 | Q3: 2030 | R3: 2031 | S3: 2032
A4: EBIT(1-tax) | B4: =FS_Forecast!B13*(1-FS_Forecast!B21) -> 5978.6253 | C4: =FS_Forecast!C13*(1-FS_Forecast!C21) -> 6321.1053 | D4: =FS_Forecast!D13*(1-FS_Forecast!D21) -> 7709.1705 | E4: =FS_Forecast!E13*(1-FS_Forecast!E21) -> 11738.359 | F4: =FS_Forecast!F13*(1-FS_Forecast!F21) -> 13469.23 | G4: =FS_Forecast!G13*(1-FS_Forecast!G21) -> 15588.383 | H4: =FS_Forecast!H13*(1-FS_Forecast!H21) -> 17033.287 | I4: =FS_Forecast!I13*(1-FS_Forecast!I21) -> 19051.369 | ... K4: =FS_Forecast!K13*(1-FS_Forecast!K21) -> 25724.566 | L4: =FS_Forecast!M13*(1-FS_Forecast!M21) -> 16568.467 | M4: =FS_Forecast!N13*(1-FS_Forecast!N21) -> 18501.273 | N4: =FS_Forecast!O13*(1-FS_Forecast!O21) -> 23268.276 | O4: =FS_Forecast!P13*(1-FS_Forecast!P21) -> 23779.862 | P4: =FS_Forecast!Q13*(1-FS_Forecast!Q21) -> 24497.691 | Q4: =FS_Forecast!R13*(1-FS_Forecast!R21) -> 25438.069 | R4: =FS_Forecast!S13*(1-FS_Forecast!S21) -> 26623.138 | S4: =FS_Forecast!T13*(1-FS_Forecast!T21) -> 28087.41
A5: (+) Depriciation | B5: =Financials!C11 -> 1693 | C5: =Financials!D11 -> 2055 | D5: =Financials!E11 -> 2245 | E5: =Financials!F11 -> 2428 | F5: =Financials!G11 -> 2720 | G5: =Financials!H11 -> 2891 | H5: =Financials!I11 -> 3103 | I5: =Financials!J11 -> 3400 | ... K5: =Financials!L11 -> 4099 | L5: 4361 | M5: =FS_Forecast!N11 -> 4658.9867 | N5: =FS_Forecast!O11 -> 4723.2174 | O5: =FS_Forecast!P11 -> 4827.064 | P5: =FS_Forecast!Q11 -> 4972.7758 | Q5: =FS_Forecast!R11 -> 5163.6628 | R5: =FS_Forecast!S11 -> 5404.2194 | S5: =FS_Forecast!T11 -> 5701.4514
A6: (-) Capex | B6: 1556 | C6: 1705 | D6: 2023 | E6: 2063 | F6: 2071 | G6: 2051 | H6: 2454 | I6: 2802 | J6: 3386 | K6: 3499 | L6: 3622 | M6: =$M$9*FS_Forecast!N4 -> 4163.8663 | N6: =$M$9*FS_Forecast!O4 -> 4221.2711 | O6: =$M$9*FS_Forecast!P4 -> 4314.0818 | P6: =$M$9*FS_Forecast!Q4 -> 4444.3084 | Q6: =$M$9*FS_Forecast!R4 -> 4614.9095 | R6: =$M$9*FS_Forecast!S4 -> 4829.9016 | S6: =$M$9*FS_Forecast!T4 -> 5095.5462
A7: Change in NWC | B7: =FS_Forecast!C41 -> 2235 | C7: =FS_Forecast!D41 -> -3166 | D7: =FS_Forecast!E41 -> -4553 | E7: =FS_Forecast!F41 -> -787 | F7: =FS_Forecast!G41 -> -2699 | G7: =FS_Forecast!H41 -> -5141 | H7: =FS_Forecast!I41 -> -3530 | I7: =FS_Forecast!J41 -> -7786 | ... S7: =FS_Forecast!T41 -> -3138.2335
A8: Free Cash Flows | B8: =B4+B5-B6-B7 -> 3880.6253 | C8: =C4+C5-C6-C7 -> 9837.1053 | D8: =D4+D5-D6-D7 -> 12484.171 | E8: =E4+E5-E6-E7 -> 12890.359 | F8: =F4+F5-F6-F7 -> 16817.23 | G8: =G4+G5-G6-G7 -> 21569.383 | H8: =H4+H5-H6-H7 -> 21212.287 | I8: =I4+I5-I6-I7 -> 27435.369 | ... S8: =S4+S5-S6-S7 -> 31831.549
B9: =B6/Financials!B4 -> 0.011925748 | C9: =C6/Financials!C4 -> 0.010852476 | D9: =D6/Financials!D4 -> 0.010944601 | E9: =E6/Financials!E4 -> 0.010255569 | F9: =F6/Financials!F4 -> 0.0091537125 | G9: =G6/Financials!G4 -> 0.0084697818 | H9: =H6/Financials!H4 -> 0.0095434023 | I9: =I6/Financials!I4 -> 0.0097427998 | ... K9: =K6/Financials!K4 -> 0.0094154813 | L9: =L6/FS_Forecast!M4 -> 0.0080926431 | M9: =IFERROR(__xludf.DUMMYFUNCTION("AVERAGE.WEIGHTED(B9:L9,B10:L10)"),0.009484889162893884) -> 0.0094848892
B10: 1 | C10: 2 | D10: 3 | E10: 4 | F10: 5 | G10: 6 | H10: 7 | I10: 8 | J10: 9 | K10: 10 | L10: 11
M11: 1 | N11: 2 | O11: 3 | P11: 4 | Q11: 5 | R11: 6 | S11: 7
M12: =M8/(1+$B$24)^M11 -> 21545.848 | N12: =N8/(1+$B$24)^N11 -> 20689.209 | O12: =O8/(1+$B$24)^O11 -> 21149.322 | P12: =P8/(1+$B$24)^P11 -> 20820.841 | Q12: =Q8/(1+$B$24)^Q11 -> 20650.775 | R12: =R8/(1+$B$24)^R11 -> 20634.489 | S12: =S8/(1+$B$24)^S11 -> 20782.543
F13: Terminal Growth Rate | H13: 0.02
A14: WACC Calculation | F14: 2032 FCF x (1+g) | H14: =S8*(1+H13) -> 32468.18 | J14: hjbjb
A15: Risk Free Rate | B15: 0.0414 | F15: Terminal value in 2027 | H15: =H14/(B24-H13) -> 758613.09 | J15: =K15-K13 -> 0
A16: Market Risk Premium | B16: 0.0638 | F16: Present Value of Terminal Value | H16: =H15/J18 -> 495291.92 | M16: =SUM(M12:S12) -> 146273.03
A17: Beta | B17: 0.43 | F17: Present Value of Projected Cash Flows | H17: =SUM(L12:U12) -> 146273.03
A18: Cost Of Equity | B18: =B15+(B17*B16) -> 0.068834 | F18: Total enterprise value (TEV) | H18: =SUM(H16:H17) -> 641564.95 | J18: =(1+B24)^S11 -> 1.5316484
A19: Value Of Equity | B19: =Sheet3!M4 -> 262693.6 | F19: Non Operating Assets | H19: =Financials!M42 -> 54251
A20: YTM | B20: 0.0534 | F20: Terminal value as % of TEV | H20: =H16/H18 -> 0.77200589
A21: Tax Rate | B21: 0.21
A22: Cost Of Debt | B22: =B20*(1-B21) -> 0.042186
A23: Value Of Debt | B23: =Sheet3!M5+H28 -> 76904 | F23: Valuation
A24: WACC | B24: =B26+B27 -> 0.062799394
H25: Perpetuity
A26: =B19/A30 -> 0.77354375 | B26: =A26*B18 -> 0.05324611 | F26: Enterprise value | H26: =H18+H19 -> 695815.95
A27: =B23/A30 -> 0.22645625 | B27: =B22*A27 -> 0.0095532835 | F27: Outstanding debt | H27: =Sheet3!M5+I27 -> 72359
F28: Short term Borrowings | H28: 4545
F29: Non controlling Interests | H29: 9933
A30: =B19+B23 -> 339597.6 | F30: Operating Lease | H30: 4889
F31: Equity value | H31: =H26-H27-H29-H30-H28 -> 604089.95
F32: Shares Outstanding | H32: 907.67
F33: Equity Value Per Share | H33: =H31/H32 -> 665.53918

Sheet Sheet3
B2: Adj Close
A3: 44256 | B3: 290 | C3: 6909.51 | E3: =SLOPE(H4:H263,I4:I263) -> 0.32298712
A4: 44287 | B4: 286.93 | C4: 6939.03 | H4: -0.0109 | I4: 0.0107 | K4: =4.08+0.323*(6) -> 6.018 | M4: =905.84*290 -> 262693.6
A5: 44317 | B5: 330.11 | C5: 6845.5 | E5: =COVAR(B3:B55,C3:C55) -> -51372.093 | H5: 0.0598 | I5: -0.0139 | K5: 3 | M5: 72359
A6: 44348 | B6: 329.77 | C6: 6849.09 | E6: =VAR(C3:C55) -> 975450.6 | H6: -0.0358 | I6: -0.001 | M6: =SUM(M4:M5) -> 335052.6
A7: 44378 | B7: 341.56 | C7: 6840.2 | H7: -0.1946 | I7: 0.0034
A8: 44409 | B8: 345.3 | C8: 6688.46 | H8: 0.0762 | I8: -0.0035 | M8: =M5/M4 -> 0.27545018
A9: 44440 | B9: 309.87 | C9: 6460.26 | F9: =COVAR(H4:H263,I4:I263) -> 0.00015750513 | H9: -0.0377 | I9: -0.0038 | K9: =(M4/M6)*K4 -> 4.718334 | M9: =(1-0.28)*M8 -> 0.19832413 | N9: =1+M9 -> 1.1983241
A10: 44470 | B10: 249.56 | C10: 6339.39 | F10: =VAR(I4:I263) -> 0.00048953426 | H10: 0.0225 | I10: 0.0157 | K10: =(M5/M6)*K5 -> 0.64788932 | N10: =0.323*N9 -> 0.38705869
A11: 44501 | B11: 311.97 | C11: 6204.95 | F11: =F9/F10 -> 0.32174486 | H11: 0.0138 | I11: -0.0103 | K11: =SUM(K9:K10) -> 5.3662233
A12: 44531 | B12: 301.91 | C12: 5911.69 | H12: 0.0135 | I12: 0.014
A13: 44562 | B13: 411.44 | C13: 5569.06 | H13: -0.0422 | I13: 0.001 | L13: =SLOPE(I4:I263,H4:H263) -> 0.073301228
A14: 44593 | B14: 523.75 | C14: 5611.85 | H14: 0.033 | I14: -0.0063
A15: 44621 | B15: 474.96 | C15: 5954.5 | H15: 0.0035 | I15: 0.0031
A16: 44652 | B16: 542.49 | C16: 6040.53 | H16: 0.0306 | I16: 0.0373
A17: 44682 | B17: 505.86 | C17: 5881.63 | H17: -0.0059 | I17: -0.0195
A18: 44713 | B18: 610.2 | C18: 6032.38 | H18: -0.0072 | I18: 0.0008
A19: 44743 | B19: 564.5 | C19: 5705.45 | H19: -0.0508 | I19: -0.0163
A20: 44774 | B20: 584.68 | C20: 5762.48 | H20: -0.0578 | I20: 0.0071
A21: 44805 | B21: 590.2 | C21: 5648.4 | H21: 0.0165 | I21: 0.0192
A22: 44835 | B22: 576.16 | C22: 5522.3 | H22: 0.0059 | I22: 0.017
A23: 44866 | B23: 509.26 | C23: 5460.48 | H23: -0.0158 | I23: -0.0243
A24: 44896 | B24: 495.37 | C24: 5277.51 | H24: 0.0468 | I24: 0.0109
A25: 44927 | B25: 483.7 | C25: 5035.69 | H25: 0.0219 | I25: -0.0031
... A62: 46054 | B62: 372.07 | C62: 3972.89 | H62: 0.015 | I62: -0.0194
H63: 0.0059 | I63: -0.0048
H64: 0.0197 | I64: 0.0067
H65: -0.0391 | I65: -0.0199
H66: -0.053 | I66: -0.0064
H67: -0.0993 | I67: 0.0096
H68: 0.0327 | I68: 0.0106
H69: -0.0023 | I69: 0.0168
H70: -0.0383 | I70: -0.0208
H71: 0.085 | I71: 0.0466
H72: 0.0053 | I72: -0.0137
H73: -0.0089 | I73: -0.0096
H74: -0.0476 | I74: 0.0085
... H263: 0.0448 | I263: 0.0081
